Workbook

Sheet Notes
A1: This is an example sheet with made-up data to showcase visualization

Sheet Experimental_parameters
A1: Tall tubes | B1: Species | C1: Strain | D1: Starting gravity (Plato) | E1: Inoculum density (cells/mL) | F1: Temperature (°C) | G1: Experiment number | H1: Date start experiment | I1: # of replicates | J1: Pitch
A2: 1 | B2: Saccharomyces pastorianus | C2: strain-1 | D2: 17 | E2: 5000000 | F2: 12 | G2: 1000 | H2: 46268 | I2: 2 | J2: 1
A3: 2

Sheet Planning_preculture
A1: PROCEDURE
A3: 44442 | B3: Inoculate wake-up cultures: Stock in 100mL YPD.
B4: Incubate at 12°C and 200rpm.
A6: 44445 | B6: Transfer wake-up culture to YPM6% preculture at an OD of 0.8 in 4x100mL Shake Flasks.
B8: Details wake-up culture:
C9: Dilution | F9: Volume to transfer to preculture:
C10: OD1
C11: OD2 | G11: =0.8*100/D12 -> #DIV/0! | H11: mL
C12: OD660 | D12: =D9*AVERAGE(D10:D11) -> #DIV/0!
B14: Incubate at 12°C and 200rpm.
A16: 44447 | B16: Start Tall Tube experiment
B18: 1. | C18: Inoculum preparation.
C20: Details preculture:
D21: Dilution | E21: 50
D22: OD1 | E22: 0.176
D23: OD2 | E23: 0.159
D24: OD660 | E24: =E21*AVERAGE(E22:E23) -> 8.375
D25: Resuspension volume for OD660 = ~20 | E25: =E24*500/20 -> 209.375 | F25: mL →→ | G25: Spin down and resuspend in | J25: 150 | K25: mL
C27: Cell count resuspension: | H27: Inoculum
D28: Total count | H28: Volume | I28: 5000 | J28: ml
D29: Dead count | H29: Cell count | I29: =5000000 -> 5000000 | J29: Cell/ml
D30: Viability | E30: =1-(AVERAGE(E29:F29)/AVERAGE(E28:F28)) -> #DIV/0! | I30: Resuspension: | J30: =I29*I28/E31 -> #DIV/0! | K30: mL
D31: Viable count | E31: =AVERAGE(E28:F28)*E30 -> #DIV/0! | F31: cells/mL | I31: Water: | J31: =200-J30 -> #DIV/0! | K31: mL
B33: 2. | C33: Fill each Tall Tube with 2395g of inoculated 21°P wort
B35: 3. | D35: Start logging of MFM
D36: First sample
B38: Last sample
D39: Diacetyl < threshold | G39: °P End?
D43: Viability at the cone

Sheet CellCount_Viability
A1: Date | B1: Time (h) | C1: Time (days) | D1: 1 Dead cells | E1: 1 Total cells | F1: 1 Viability (%) | G1: 2 Dead cells | H1: 2 Total cells | I1: 2 Viability (%)
A2: 46268 | B2: =C2*24 -> 0 | C2: =IF(NOT(A2=0),A2-$A$2,"") -> 0 | D2: 10000 | E2: 4862000 | F2: =(E2-D2)/E2 -> 0.99794323 | G2: 10000 | H2: 4732200 | I2: =(H2-G2)/H2 -> 0.99788682
A3: 46269 | B3: =C3*24 -> 24 | C3: =IF(NOT(A3=0),A3-$A$2,"") -> 1 | D3: 20000 | E3: 14175000 | F3: =(E3-D3)/E3 -> 0.99858907 | G3: 20000 | H3: 13974000 | I3: =(H3-G3)/H3 -> 0.99856877
A4: 46270 | B4: =C4*24 -> 48 | C4: =IF(NOT(A4=0),A4-$A$2,"") -> 2 | D4: 30000 | E4: 32590800 | F4: =(E4-D4)/E4 -> 0.99907949 | G4: 30000 | H4: 31570000 | I4: =(H4-G4)/H4 -> 0.99904973
A5: 46271 | B5: =C5*24 -> 72 | C5: =IF(NOT(A5=0),A5-$A$2,"") -> 3 | D5: 40000 | E5: 40902000 | F5: =(E5-D5)/E5 -> 0.99902205 | G5: 40000 | H5: 43804800 | I5: =(H5-G5)/H5 -> 0.99908686
A6: 46272 | B6: =C6*24 -> 96 | C6: =IF(NOT(A6=0),A6-$A$2,"") -> 4 | D6: 50000 | E6: 38494000 | F6: =(E6-D6)/E6 -> 0.9987011 | G6: 50000 | H6: 40986000 | I6: =(H6-G6)/H6 -> 0.99878007
A7: 46273 | B7: =C7*24 -> 120 | C7: =IF(NOT(A7=0),A7-$A$2,"") -> 5 | D7: 60000 | E7: 37886800 | F7: =(E7-D7)/E7 -> 0.99841633 | G7: 60000 | H7: 37788800 | I7: =(H7-G7)/H7 -> 0.99841223
A8: 46274 | B8: =C8*24 -> 144 | C8: =IF(NOT(A8=0),A8-$A$2,"") -> 6 | D8: 70000 | E8: 15606000 | F8: =(E8-D8)/E8 -> 0.99551455 | G8: 70000 | H8: 10925000 | I8: =(H8-G8)/H8 -> 0.99359268
A9: 46275 | B9: =C9*24 -> 168 | C9: =IF(NOT(A9=0),A9-$A$2,"") -> 7 | D9: 80000 | E9: 5220800 | F9: =(E9-D9)/E9 -> 0.98467668 | G9: 80000 | H9: 5777000 | I9: =(H9-G9)/H9 -> 0.98615198
A10: 46276 | B10: =C10*24 -> 192 | C10: =IF(NOT(A10=0),A10-$A$2,"") -> 8 | D10: 90000 | E10: 2475000 | F10: =(E10-D10)/E10 -> 0.96363636 | G10: 90000 | H10: 2998800 | I10: =(H10-G10)/H10 -> 0.969988
A11: 46277 | B11: =C11*24 -> 216 | C11: =IF(NOT(A11=0),A11-$A$2,"") -> 9 | D11: 100000 | E11: 2310800 | F11: =(E11-D11)/E11 -> 0.95672494 | G11: 100000 | H11: 2415000 | I11: =(H11-G11)/H11 -> 0.95859213
A12: 46278 | B12: =C12*24 -> 240 | C12: =IF(NOT(A12=0),A12-$A$2,"") -> 10 | D12: 110000 | E12: 1710000 | F12: =(E12-D12)/E12 -> 0.93567251 | G12: 110000 | H12: 1900000 | I12: =(H12-G12)/H12 -> 0.94210526
A13: 0 | B13: =C13*24 -> #VALUE! | C13: =IF(NOT(A13=0),A13-$A$2,"") | D13: #N/A | E13: #N/A | F13: =(E13-D13)/E13 -> #N/A | G13: #N/A | H13: #N/A | I13: =(H13-G13)/H13 -> #N/A
A14: 0 | B14: =C14*24 -> #VALUE! | C14: =IF(NOT(A14=0),A14-$A$2,"") | D14: #N/A | E14: #N/A | F14: =(E14-D14)/E14 -> #N/A | G14: #N/A | H14: #N/A | I14: =(H14-G14)/H14 -> #N/A
A15: 0 | B15: =C15*24 -> #VALUE! | C15: =IF(NOT(A15=0),A15-$A$2,"") | D15: #N/A | E15: #N/A | F15: =(E15-D15)/E15 -> #N/A | G15: #N/A | H15: #N/A | I15: =(H15-G15)/H15 -> #N/A
A16: 0 | B16: =C16*24 -> #VALUE! | C16: =IF(NOT(A16=0),A16-$A$2,"") | D16: #N/A | E16: #N/A | F16: =(E16-D16)/E16 -> #N/A | G16: #N/A | H16: #N/A | I16: =(H16-G16)/H16 -> #N/A
A17: 0 | B17: =C17*24 -> #VALUE! | C17: =IF(NOT(A17=0),A17-$A$2,"") | D17: #N/A | E17: #N/A | F17: =(E17-D17)/E17 -> #N/A | G17: #N/A | H17: #N/A | I17: =(H17-G17)/H17 -> #N/A
A18: 0 | B18: =C18*24 -> #VALUE! | C18: =IF(NOT(A18=0),A18-$A$2,"") | D18: #N/A | E18: #N/A | F18: =(E18-D18)/E18 -> #N/A | G18: #N/A | H18: #N/A | I18: =(H18-G18)/H18 -> #N/A
A19: 0 | B19: =C19*24 -> #VALUE! | C19: =IF(NOT(A19=0),A19-$A$2,"") | D19: #N/A | E19: #N/A | F19: =(E19-D19)/E19 -> #N/A | G19: #N/A | H19: #N/A | I19: =(H19-G19)/H19 -> #N/A
A20: 0 | B20: =C20*24 -> #VALUE! | C20: =IF(NOT(A20=0),A20-$A$2,"") | D20: #N/A | E20: #N/A | F20: =(E20-D20)/E20 -> #N/A | G20: #N/A | H20: #N/A | I20: =(H20-G20)/H20 -> #N/A
A21: 0 | B21: =C21*24 -> #VALUE! | C21: =IF(NOT(A21=0),A21-$A$2,"") | D21: #N/A | E21: #N/A | F21: =(E21-D21)/E21 -> #N/A | G21: #N/A | H21: #N/A | I21: =(H21-G21)/H21 -> #N/A

Sheet Attenuation
D1: =Experimental_parameters!A2 -> 1 | E1: =Experimental_parameters!A3 -> 2
A2: Date | B2: Time (h) | C2: Time (days) | D2: TT1 | E2: TT2
A3: =CellCount_Viability!A2 -> 46268 | B3: =C3*24 -> 0 | C3: =IF(NOT(A3=0),A3-$A$3,"") -> 0 | D3: 17.3 | E3: 17.127
A4: =CellCount_Viability!A3 -> 46269 | B4: =C4*24 -> 24 | C4: =IF(NOT(A4=0),A4-$A$3,"") -> 1 | D4: 16.5 | E4: 17.034
A5: =CellCount_Viability!A4 -> 46270 | B5: =C5*24 -> 48 | C5: =IF(NOT(A5=0),A5-$A$3,"") -> 2 | D5: 13.959 | E5: 15.29
A6: =CellCount_Viability!A5 -> 46271 | B6: =C6*24 -> 72 | C6: =IF(NOT(A6=0),A6-$A$3,"") -> 3 | D6: 12.138 | E6: 12.376
A7: =CellCount_Viability!A6 -> 46272 | B7: =C7*24 -> 96 | C7: =IF(NOT(A7=0),A7-$A$3,"") -> 4 | D7: 8.74 | E7: 9.108
A8: =CellCount_Viability!A7 -> 46273 | B8: =C8*24 -> 120 | C8: =IF(NOT(A8=0),A8-$A$3,"") -> 5 | D8: 6.86 | E8: 6.86
A9: =CellCount_Viability!A8 -> 46274 | B9: =C9*24 -> 144 | C9: =IF(NOT(A9=0),A9-$A$3,"") -> 6 | D9: 4.998 | E9: 4.655
A10: =CellCount_Viability!A9 -> 46275 | B10: =C10*24 -> 168 | C10: =IF(NOT(A10=0),A10-$A$3,"") -> 7 | D10: 4.784 | E10: 4.905
A11: =CellCount_Viability!A10 -> 46276 | B11: =C11*24 -> 192 | C11: =IF(NOT(A11=0),A11-$A$3,"") -> 8 | D11: 4.356 | E11: 4.386
A12: =CellCount_Viability!A11 -> 46277 | B12: =C12*24 -> 216 | C12: =IF(NOT(A12=0),A12-$A$3,"") -> 9 | D12: 4.796 | E12: 4.515
A13: =CellCount_Viability!A12 -> 46278 | B13: =C13*24 -> 240 | C13: =IF(NOT(A13=0),A13-$A$3,"") -> 10 | D13: 4.085 | E13: 3.99
A14: =CellCount_Viability!A13 -> 0 | B14: =C14*24 -> #VALUE! | C14: =IF(NOT(A14=0),A14-$A$3,"") | D14: #N/A | E14: #N/A
A15: =CellCount_Viability!A14 -> 0 | B15: =C15*24 -> #VALUE! | C15: =IF(NOT(A15=0),A15-$A$3,"") | D15: #N/A | E15: #N/A
A16: =CellCount_Viability!A15 -> 0 | B16: =C16*24 -> #VALUE! | C16: =IF(NOT(A16=0),A16-$A$3,"") | D16: #N/A | E16: #N/A
A17: =CellCount_Viability!A16 -> 0 | B17: =C17*24 -> #VALUE! | C17: =IF(NOT(A17=0),A17-$A$3,"") | D17: #N/A | E17: #N/A
A18: =CellCount_Viability!A17 -> 0 | B18: =C18*24 -> #VALUE! | C18: =IF(NOT(A18=0),A18-$A$3,"") | D18: #N/A | E18: #N/A
A19: =CellCount_Viability!A18 -> 0 | B19: =C19*24 -> #VALUE! | C19: =IF(NOT(A19=0),A19-$A$3,"") | D19: #N/A | E19: #N/A
A20: =CellCount_Viability!A19 -> 0 | B20: =C20*24 -> #VALUE! | C20: =IF(NOT(A20=0),A20-$A$3,"") | D20: #N/A | E20: #N/A
A21: =CellCount_Viability!A20 -> 0 | B21: =C21*24 -> #VALUE! | C21: =IF(NOT(A21=0),A21-$A$3,"") | D21: #N/A | E21: #N/A
A22: =CellCount_Viability!A21 -> 0 | B22: =C22*24 -> #VALUE! | C22: =IF(NOT(A22=0),A22-$A$3,"") | D22: #N/A | E22: #N/A

Sheet pH
D1: =Experimental_parameters!A2 -> 1 | E1: =Experimental_parameters!A3 -> 2
A2: Date | B2: Time (h) | C2: Time (days) | D2: TT1 | E2: TT2
A3: =CellCount_Viability!A2 -> 46268 | B3: =C3*24 -> 0 | C3: =IF(NOT(A3=0),A3-$A$3,"") -> 0 | D3: 5.533 | E3: 4.9698
A4: =CellCount_Viability!A3 -> 46269 | B4: =C4*24 -> 24 | C4: =IF(NOT(A4=0),A4-$A$3,"") -> 1 | D4: 4.76 | E4: 4.8756
A5: =CellCount_Viability!A4 -> 46270 | B5: =C5*24 -> 48 | C5: =IF(NOT(A5=0),A5-$A$3,"") -> 2 | D5: 4.4748 | E5: 4.983
A6: =CellCount_Viability!A5 -> 46271 | B6: =C6*24 -> 72 | C6: =IF(NOT(A6=0),A6-$A$3,"") -> 3 | D6: 4.488 | E6: 4.6176
A7: =CellCount_Viability!A6 -> 46272 | B7: =C7*24 -> 96 | C7: =IF(NOT(A7=0),A7-$A$3,"") -> 4 | D7: 4.0945 | E7: 4.2768
A8: =CellCount_Viability!A7 -> 46273 | B8: =C8*24 -> 120 | C8: =IF(NOT(A8=0),A8-$A$3,"") -> 5 | D8: 4.1846 | E8: 4.1846
A9: =CellCount_Viability!A8 -> 46274 | B9: =C9*24 -> 144 | C9: =IF(NOT(A9=0),A9-$A$3,"") -> 6 | D9: 4.3452 | E9: 4.047
A10: =CellCount_Viability!A9 -> 46275 | B10: =C10*24 -> 168 | C10: =IF(NOT(A10=0),A10-$A$3,"") -> 7 | D10: 4.4824 | E10: 4.687
A11: =CellCount_Viability!A10 -> 46276 | B11: =C11*24 -> 192 | C11: =IF(NOT(A11=0),A11-$A$3,"") -> 8 | D11: 4.2669 | E11: 4.4268
A12: =CellCount_Viability!A11 -> 46277 | B12: =C12*24 -> 216 | C12: =IF(NOT(A12=0),A12-$A$3,"") -> 9 | D12: 4.7306 | E12: 4.557
A13: =CellCount_Viability!A12 -> 46278 | B13: =C13*24 -> 240 | C13: =IF(NOT(A13=0),A13-$A$3,"") -> 10 | D13: 4.142 | E13: 4.1325
A14: =CellCount_Viability!A13 -> 0 | B14: =C14*24 -> #VALUE! | C14: =IF(NOT(A14=0),A14-$A$3,"") | D14: #N/A | E14: #N/A
A15: =CellCount_Viability!A14 -> 0 | B15: =C15*24 -> #VALUE! | C15: =IF(NOT(A15=0),A15-$A$3,"") | D15: #N/A | E15: #N/A
A16: =CellCount_Viability!A15 -> 0 | B16: =C16*24 -> #VALUE! | C16: =IF(NOT(A16=0),A16-$A$3,"") | D16: #N/A | E16: #N/A
A17: =CellCount_Viability!A16 -> 0 | B17: =C17*24 -> #VALUE! | C17: =IF(NOT(A17=0),A17-$A$3,"") | D17: #N/A | E17: #N/A
A18: =CellCount_Viability!A17 -> 0 | B18: =C18*24 -> #VALUE! | C18: =IF(NOT(A18=0),A18-$A$3,"") | D18: #N/A | E18: #N/A
A19: =CellCount_Viability!A18 -> 0 | B19: =C19*24 -> #VALUE! | C19: =IF(NOT(A19=0),A19-$A$3,"") | D19: #N/A | E19: #N/A
A20: =CellCount_Viability!A19 -> 0 | B20: =C20*24 -> #VALUE! | C20: =IF(NOT(A20=0),A20-$A$3,"") | D20: #N/A | E20: #N/A
A21: =CellCount_Viability!A20 -> 0 | B21: =C21*24 -> #VALUE! | C21: =IF(NOT(A21=0),A21-$A$3,"") | D21: #N/A | E21: #N/A
A22: =CellCount_Viability!A21 -> 0 | B22: =C22*24 -> #VALUE! | C22: =IF(NOT(A22=0),A22-$A$3,"") | D22: #N/A | E22: #N/A
D27: 1.1 | E27: 0.99
D28: 1 | E28: 1.02
D29: 0.99 | E29: 1.1
D30: 1.02 | E30: 1.04
D31: 0.95 | E31: 0.99
D32: 0.98 | E32: 0.98
D33: 1.02 | E33: 0.95
D34: 1.04 | E34: 1.09
D35: 0.99 | E35: 1.02
D36: 1.09 | E36: 1.05
D37: 0.95 | E37: 0.95

Sheet Cone_viability
A1: Cone viability | B1: 1 Dead cells | C1: 1 Total cells | D1: 1 Viability (%) | E1: TT1 average | F1: TT1 stdev | G1: 2 Dead cells | H1: 2 Total cells | I1: 2 Viability (%) | J1: TT2 average | K1: TT2 stdev
A2: 1 | B2: 110000 | C2: 1710000 | D2: =(C2-B2)/C2 -> 0.93567251 | E2: =_xlfn.AGGREGATE(1,6,D2:D6) -> 0.91571374 | F2: =_xlfn.AGGREGATE(7,6,D2:D6) -> 0.018067555 | G2: 100000 | H2: 1800000 | I2: =(H2-G2)/H2 -> 0.94444444 | J2: =_xlfn.AGGREGATE(1,6,I2:I6) -> 0.92144058 | K2: =_xlfn.AGGREGATE(7,6,I2:I6) -> 0.035961174
A3: 2 | B3: 210000 | C3: 2110000 | D3: =(C3-B3)/C3 -> 0.90047393 | G3: 98000 | H3: 1630000 | I3: =(H3-G3)/H3 -> 0.9398773
A4: 3 | B4: 170000 | C4: 1910000 | D4: =(C4-B4)/C4 -> 0.91099476 | G4: 180000 | H4: 1500000 | I4: =(H4-G4)/H4 -> 0.88

Sheet HPLC_raw
A1: T1 | B1: =CellCount_Viability!A2 -> 46268 | F1: Maltoheptaose | G1: Maltohexaose | H1: Maltopentao se | I1: Maltotetraose | J1: Maltotriose | K1: Maltose | L1: Glucose | M1: Fructose | N1: Glycerol | O1: Ethanol
A2: MT01-MTT-260_CBS1483_17P-s10a | C2: D2F-A3 | E2: 1 | F2: 1.39 | G2: 1.98 | H2: 2.26 | I2: 5.28 | J2: 26.942385 | K2: 86.334395 | L2: 20.24226 | M2: 7.856225 | N2: 0 | O2: 0.772485
A3: MT01-MTT-260_CBS1483_17P-s10b | C3: D2F-B3 | E3: 1 | F3: 1.4735022 | G3: 1.9843252 | H3: 2.4231065 | I3: 5.6250642 | J3: 29.392615 | K3: 87.709438 | L3: 20.828936 | M3: 8.0467368 | N3: 0 | O3: 0.8213826 | Q3: =F2+RAND()*0.1*F$2*$AC3 -> 1.3858954 | R3: =G2+RAND()*0.1*G$2*$AC3 -> 1.9703372 | S3: =H2+RAND()*0.1*H$2*$AC3 -> 2.1217539 | T3: =I2+RAND()*0.1*I$2*$AC3 -> 5.039149 | U3: =J2+RAND()*0.1*J$2*$AC3 -> 26.129547 | V3: =K2+RAND()*0.1*K$2*$AC3 -> 82.607923 | W3: =L2+RAND()*0.1*L$2*$AC3 -> 18.876832 | X3: =M2+RAND()*0.1*M$2*$AC3 -> 7.6875978 | Y3: =N2+RAND()*0.1*N$2*$AC3 -> 0 | Z3: =O3+RAND()*0.1*O$2*$AC3 -> 0.77665154 | AB3: =RAND() -> 0.85319292 | AC3: =IF(AB3>0.5,-1,1) -> -1
A4: MT02-MTT-260_CBS1483_17P-s10a | C4: D2F-C3 | E4: 1 | F4: 1.3751697 | G4: 1.9079447 | H4: 2.1430263 | I4: 4.955885 | J4: 25.2157 | K4: 86.086046 | L4: 19.909029 | M4: 7.539648 | N4: 0 | O4: 0.69851361 | Q4: =F3+RAND()*0.1*F$2*$AC4 -> 1.4808597 | R4: =G3+RAND()*0.1*G$2*$AC4 -> 2.0983488 | S4: =H3+RAND()*0.1*H$2*$AC4 -> 2.4511903 | T4: =I3+RAND()*0.1*I$2*$AC4 -> 5.9901755 | U4: =J3+RAND()*0.1*J$2*$AC4 -> 30.224517 | V4: =K3+RAND()*0.1*K$2*$AC4 -> 88.197675 | W4: =L3+RAND()*0.1*L$2*$AC4 -> 21.276621 | X4: =M3+RAND()*0.1*M$2*$AC4 -> 8.1073399 | ... Z4: =O3+RAND()*0.1*O$2*$AC4 -> 0.89212897 | AB4: =RAND() -> 0.001545262 | AC4: =IF(AB4>0.5,-1,1) -> 1
A5: MT02-MTT-260_CBS1483_17P-s10b | C5: D2F-D3 | E5: 1 | F5: 1.3061014 | G5: 1.9043378 | H5: 2.0417964 | I5: 4.8638422 | J5: 25.271712 | K5: 78.554664 | L5: 18.269822 | M5: 7.1126854 | N5: 0 | O5: 0.71921289 | Q5: =F4+RAND()*0.1*F$2*$AC5 -> 1.2897225 | R5: =G4+RAND()*0.1*G$2*$AC5 -> 1.8272235 | S5: =H4+RAND()*0.1*H$2*$AC5 -> 2.0539774 | T5: =I4+RAND()*0.1*I$2*$AC5 -> 4.8928274 | U5: =J4+RAND()*0.1*J$2*$AC5 -> 24.737969 | V5: =K4+RAND()*0.1*K$2*$AC5 -> 82.736778 | W5: =L4+RAND()*0.1*L$2*$AC5 -> 19.050497 | X5: =M4+RAND()*0.1*M$2*$AC5 -> 7.4377111 | ... Z5: =O4+RAND()*0.1*O$2*$AC5 -> 0.6480533 | AB5: =RAND() -> 0.6314717 | AC5: =IF(AB5>0.5,-1,1) -> -1
A7: T2 | B7: =CellCount_Viability!A3 -> 46269 | F7: Maltoheptaose | G7: Maltohexaose | H7: Maltopentao se | I7: Maltotetraose | J7: Maltotriose | K7: Maltose | L7: Glucose | M7: Fructose | N7: Glycerol | O7: Ethanol
A8: MT01-MTT-260_CBS1483_17P-S2a | C8: D2F-A4 | E8: 1 | F8: 1.39 | G8: 1.98 | H8: 2.26 | I8: 5.28 | J8: 28.1985 | K8: 79.4878 | L8: 15.057 | M8: 6.365 | N8: 0.44805 | O8: 3.9456
A9: MT01-MTT-260_CBS1483_17P-S2b | C9: D2F-B4 | E9: 1 | F9: 1.475645 | G9: 2.1700287 | H9: 2.477804 | I9: 5.6955847 | J9: 30.107174 | K9: 82.268747 | L9: 15.115613 | M9: 6.3816882 | N9: 0.4830953 | O9: 3.9754122 | Q9: =F8+RAND()*0.1*F8*$AC9 -> 1.2688352 | R9: =G8+RAND()*0.1*G8*$AC9 -> 1.8914756 | S9: =H8+RAND()*0.1*H8*$AC9 -> 2.0809251 | T9: =I8+RAND()*0.1*I8*$AC9 -> 4.7850522 | U9: =J8+RAND()*0.1*J8*$AC9 -> 27.41602 | V9: =K8+RAND()*0.1*K8*$AC9 -> 75.183669 | W9: =L8+RAND()*0.1*L8*$AC9 -> 13.570895 | X9: =M8+RAND()*0.1*M8*$AC9 -> 5.8850878 | ... Z9: =O8+RAND()*0.1*O8*$AC9 -> 3.6509685 | AB9: =RAND() -> 0.95333244 | AC9: =IF(AB9>0.5,-1,1) -> -1
A10: MT02-MTT-260_CBS1483_17P-S2a | C10: D2F-C4 | E10: 1 | F10: 1.4528711 | G10: 2.1534707 | H10: 2.2754432 | I10: 5.560527 | J10: 29.412766 | K10: 83.955021 | L10: 16.43468 | M10: 6.6992746 | N10: 0.48091672 | O10: 4.3306834 | Q10: =F9+RAND()*0.1*F9*$AC10 -> 1.4893337 | R10: =G9+RAND()*0.1*G9*$AC10 -> 2.1826435 | S10: =H9+RAND()*0.1*H9*$AC10 -> 2.6000874 | T10: =I9+RAND()*0.1*I9*$AC10 -> 6.1022945 | U10: =J9+RAND()*0.1*J9*$AC10 -> 32.675465 | V10: =K9+RAND()*0.1*K9*$AC10 -> 89.04283 | W10: =L9+RAND()*0.1*L9*$AC10 -> 16.283362 | X10: =M9+RAND()*0.1*M9*$AC10 -> 6.7380407 | ... Z10: =O9+RAND()*0.1*O9*$AC10 -> 4.0642837 | AB10: =RAND() -> 0.11534867 | AC10: =IF(AB10>0.5,-1,1) -> 1
A11: MT02-MTT-260_CBS1483_17P-S2b | C11: D2F-D4 | E11: 1 | F11: 1.5191712 | G11: 2.1428144 | H11: 2.4504354 | I11: 5.5967404 | J11: 29.464914 | K11: 84.999987 | L11: 16.383557 | M11: 6.7229295 | N11: 0.45465547 | O11: 4.3048177 | Q11: =F10+RAND()*0.1*F10*$AC11 -> 1.5286634 | R11: =G10+RAND()*0.1*G10*$AC11 -> 2.3075937 | S11: =H10+RAND()*0.1*H10*$AC11 -> 2.3425985 | T11: =I10+RAND()*0.1*I10*$AC11 -> 5.7981334 | U11: =J10+RAND()*0.1*J10*$AC11 -> 29.545005 | V11: =K10+RAND()*0.1*K10*$AC11 -> 85.22474 | W11: =L10+RAND()*0.1*L10*$AC11 -> 17.458924 | X11: =M10+RAND()*0.1*M10*$AC11 -> 7.1054773 | ... Z11: =O10+RAND()*0.1*O10*$AC11 -> 4.7305443 | AB11: =RAND() -> 0.34706288 | AC11: =IF(AB11>0.5,-1,1) -> 1
A13: T3 | B13: =CellCount_Viability!A4 -> 46270 | F13: Maltoheptaose | G13: Maltohexaose | H13: Maltopentao se | I13: Maltotetraose | J13: Maltotriose | K13: Maltose | L13: Glucose | M13: Fructose | N13: Glycerol | O13: Ethanol
A14: MT01-MTT-260_CBS1483_17P-S3a | C14: D2F-A6 | E14: 1 | F14: 1.39 | G14: 1.98 | H14: 2.26 | I14: 5.28 | J14: 26.788575 | K14: 75.51341 | L14: 14.30415 | M14: 6.04675 | N14: 0.4256475 | O14: 3.74832
A15: MT01-MTT-260_CBS1483_17P-S3b | C15: D2F-B6 | E15: 1 | F15: 1.3407401 | G15: 1.9695819 | H15: 2.0984753 | I15: 4.9610019 | J15: 25.089905 | K15: 69.592721 | L15: 13.165489 | M15: 6.0323936 | N15: 0.41708445 | O15: 3.5874725 | Q15: =F14+RAND()*0.1*F14*$AC15 -> 1.4445143 | R15: =G14+RAND()*0.1*G14*$AC15 -> 2.0632551 | S15: =H14+RAND()*0.1*H14*$AC15 -> 2.287774 | T15: =I14+RAND()*0.1*I14*$AC15 -> 5.5908742 | U15: =J14+RAND()*0.1*J14*$AC15 -> 27.92444 | V15: =K14+RAND()*0.1*K14*$AC15 -> 75.972475 | W15: =L14+RAND()*0.1*L14*$AC15 -> 14.69332 | X15: =M14+RAND()*0.1*M14*$AC15 -> 6.645835 | ... Z15: =O14+RAND()*0.1*O14*$AC15 -> 4.0325749 | AB15: =RAND() -> 0.29768812 | AC15: =IF(AB15>0.5,-1,1) -> 1
A16: MT02-MTT-260_CBS1483_17P-S3a | C16: D2F-C6 | E16: 1 | F16: 1.3443001 | G16: 1.8064107 | H16: 2.2404705 | I16: 5.1946226 | J16: 24.906745 | K16: 75.119817 | L16: 14.203539 | M16: 5.6624444 | N16: 0.39229312 | O16: 3.4238976 | Q16: =F15+RAND()*0.1*F15*$AC16 -> 1.400193 | R16: =G15+RAND()*0.1*G15*$AC16 -> 2.161614 | S16: =H15+RAND()*0.1*H15*$AC16 -> 2.3069432 | T16: =I15+RAND()*0.1*I15*$AC16 -> 5.3474268 | U16: =J15+RAND()*0.1*J15*$AC16 -> 26.870343 | V16: =K15+RAND()*0.1*K15*$AC16 -> 71.223875 | W16: =L15+RAND()*0.1*L15*$AC16 -> 13.747675 | X16: =M15+RAND()*0.1*M15*$AC16 -> 6.5632045 | ... Z16: =O15+RAND()*0.1*O15*$AC16 -> 3.8470982 | AB16: =RAND() -> 0.076448281 | AC16: =IF(AB16>0.5,-1,1) -> 1
A17: MT02-MTT-260_CBS1483_17P-S3b | C17: D2F-D6 | E17: 1 | F17: 1.3847775 | G17: 1.8690812 | H17: 2.116004 | I17: 5.0399627 | J17: 25.169152 | K17: 69.401115 | L17: 13.09077 | M17: 5.8154344 | N17: 0.38544164 | O17: 3.4893134 | Q17: =F16+RAND()*0.1*F16*$AC17 -> 1.3684187 | R17: =G16+RAND()*0.1*G16*$AC17 -> 1.9078986 | S17: =H16+RAND()*0.1*H16*$AC17 -> 2.3445991 | T17: =I16+RAND()*0.1*I16*$AC17 -> 5.3928245 | U17: =J16+RAND()*0.1*J16*$AC17 -> 27.00648 | V17: =K16+RAND()*0.1*K16*$AC17 -> 79.383811 | W17: =L16+RAND()*0.1*L16*$AC17 -> 15.470597 | X17: =M16+RAND()*0.1*M16*$AC17 -> 5.7550102 | ... Z17: =O16+RAND()*0.1*O16*$AC17 -> 3.7538513 | AB17: =RAND() -> 0.33530241 | AC17: =IF(AB17>0.5,-1,1) -> 1
A19: T4 | B19: =CellCount_Viability!A5 -> 46271 | F19: Maltoheptaose | G19: Maltohexaose | H19: Maltopentao se | I19: Maltotetraose | J19: Maltotriose | K19: Maltose | L19: Glucose | M19: Fructose | N19: Glycerol | O19: Ethanol
A20: MT01-MTT-260_CBS1483_17P-S4a | C20: D2B-A1 | E20: 1 | F20: 1.39 | G20: 1.98 | H20: 2.26 | I20: 5.28 | J20: 26.3725 | K20: 55.1838 | L20: 3.22875 | M20: 3.67175 | N20: 1.5141 | O20: 26.4096
A21: MT01-MTT-260_CBS1483_17P-S4b | C21: D2B-B1 | E21: 1 | F21: 1.3035427 | G21: 1.8138698 | H21: 2.0380927 | I21: 5.2048815 | J21: 26.025311 | K21: 52.858212 | L21: 3.2094501 | M21: 3.5426309 | N21: 1.4825672 | O21: 24.328811 | Q21: =F20+RAND()*0.1*F20*$AC21 -> 1.5158664 | R21: =G20+RAND()*0.1*G20*$AC21 -> 2.0576602 | S21: =H20+RAND()*0.1*H20*$AC21 -> 2.4801945 | T21: =I20+RAND()*0.1*I20*$AC21 -> 5.6792176 | U21: =J20+RAND()*0.1*J20*$AC21 -> 28.469652 | V21: =K20+RAND()*0.1*K20*$AC21 -> 60.484832 | W21: =L20+RAND()*0.1*L20*$AC21 -> 3.4573643 | X21: =M20+RAND()*0.1*M20*$AC21 -> 3.7258327 | ... Z21: =O20+RAND()*0.1*O20*$AC21 -> 27.856142 | AB21: =RAND() -> 0.41382756 | AC21: =IF(AB21>0.5,-1,1) -> 1
A22: MT02-MTT-260_CBS1483_17P-S4a | C22: D2B-C1 | E22: 1 | F22: 1.2903475 | G22: 1.9573992 | H22: 2.1243747 | I22: 4.9880837 | J22: 24.100979 | K22: 54.602925 | L22: 3.1052026 | M22: 3.5368488 | N22: 1.4724185 | O22: 24.684251 | Q22: =F21+RAND()*0.1*F21*$AC22 -> 1.3987154 | R22: =G21+RAND()*0.1*G21*$AC22 -> 1.8593143 | S22: =H21+RAND()*0.1*H21*$AC22 -> 2.1061573 | T22: =I21+RAND()*0.1*I21*$AC22 -> 5.571996 | U22: =J21+RAND()*0.1*J21*$AC22 -> 26.872021 | V22: =K21+RAND()*0.1*K21*$AC22 -> 55.781672 | W22: =L21+RAND()*0.1*L21*$AC22 -> 3.2663872 | X22: =M21+RAND()*0.1*M21*$AC22 -> 3.5687591 | ... Z22: =O21+RAND()*0.1*O21*$AC22 -> 24.427255 | AB22: =RAND() -> 0.45018994 | AC22: =IF(AB22>0.5,-1,1) -> 1
A23: MT02-MTT-260_CBS1483_17P-S4b | C23: D2B-D1 | E23: 1 | F23: 1.4473291 | G23: 2.053986 | H23: 2.4078976 | I23: 5.2809783 | J23: 27.440365 | K23: 59.194062 | L23: 3.5444025 | M23: 3.9140854 | N23: 1.5558999 | O23: 27.422575 | Q23: =F22+RAND()*0.1*F22*$AC23 -> 1.173109 | R23: =G22+RAND()*0.1*G22*$AC23 -> 1.8498332 | S23: =H22+RAND()*0.1*H22*$AC23 -> 2.1012905 | T23: =I22+RAND()*0.1*I22*$AC23 -> 4.6935696 | U23: =J22+RAND()*0.1*J22*$AC23 -> 23.438747 | V23: =K22+RAND()*0.1*K22*$AC23 -> 50.751859 | W23: =L22+RAND()*0.1*L22*$AC23 -> 3.0439171 | X23: =M22+RAND()*0.1*M22*$AC23 -> 3.4978384 | ... Z23: =O22+RAND()*0.1*O22*$AC23 -> 23.792414 | AB23: =RAND() -> 0.76504735 | AC23: =IF(AB23>0.5,-1,1) -> -1
A25: T5 | B25: =CellCount_Viability!A6 -> 46272 | F25: Maltoheptaose | G25: Maltohexaose | H25: Maltopentao se | I25: Maltotetraose | J25: Maltotriose | K25: Maltose | L25: Glucose | M25: Fructose | N25: Glycerol | O25: Ethanol
A26: MT01-MTT-260_CBS1483_17P-S5a | C26: D2F-A1 | E26: 1 | F26: 1.39 | G26: 1.98 | H26: 2.26 | I26: 5.28 | J26: 25.0525 | K26: 36.4119 | L26: 0 | M26: 1.767 | N26: 1.9776 | O26: 33.9984
A27: MT01-MTT-260_CBS1483_17P-S5b | C27: D2F-B1 | E27: 1 | F27: 1.4690634 | G27: 2.0377215 | H27: 2.263527 | I27: 5.5776635 | J27: 26.120979 | K27: 38.253619 | L27: 0 | M27: 1.8929599 | N27: 2.13543 | O27: 35.951832 | Q27: =F26+RAND()*0.1*F26*$AC27 -> 1.3067045 | R27: =G26+RAND()*0.1*G26*$AC27 -> 1.8381292 | S27: =H26+RAND()*0.1*H26*$AC27 -> 2.220062 | T27: =I26+RAND()*0.1*I26*$AC27 -> 4.753644 | U27: =J26+RAND()*0.1*J26*$AC27 -> 23.539253 | V27: =K26+RAND()*0.1*K26*$AC27 -> 35.252588 | W27: =L26+RAND()*0.1*L26*$AC27 -> 0 | X27: =M26+RAND()*0.1*M26*$AC27 -> 1.7566169 | ... Z27: =O26+RAND()*0.1*O26*$AC27 -> 32.664286 | AB27: =RAND() -> 0.74025422 | AC27: =IF(AB27>0.5,-1,1) -> -1
A28: MT02-MTT-260_CBS1483_17P-S5a | C28: D2F-C1 | E28: 1 | F28: 1.3610222 | G28: 1.8069907 | H28: 2.2117797 | I28: 4.985013 | J28: 24.82296 | K28: 34.296971 | L28: 0 | M28: 1.7182177 | N28: 1.785001 | O28: 30.806775 | Q28: =F27+RAND()*0.1*F27*$AC28 -> 1.366061 | R28: =G27+RAND()*0.1*G27*$AC28 -> 1.844943 | S28: =H27+RAND()*0.1*H27*$AC28 -> 2.2492902 | T28: =I27+RAND()*0.1*I27*$AC28 -> 5.2336038 | U28: =J27+RAND()*0.1*J27*$AC28 -> 24.471248 | V28: =K27+RAND()*0.1*K27*$AC28 -> 35.249106 | W28: =L27+RAND()*0.1*L27*$AC28 -> 0 | X28: =M27+RAND()*0.1*M27*$AC28 -> 1.8834632 | ... Z28: =O27+RAND()*0.1*O27*$AC28 -> 33.467921 | AB28: =RAND() -> 0.73877933 | AC28: =IF(AB28>0.5,-1,1) -> -1
A29: MT02-MTT-260_CBS1483_17P-S5b | C29: D2F-D1 | E29: 1 | F29: 1.3814277 | G29: 1.8243475 | H29: 2.0743451 | I29: 5.1991272 | J29: 24.448293 | K29: 32.810549 | L29: 0 | M29: 1.6221765 | N29: 1.8075027 | O29: 33.876394 | Q29: =F28+RAND()*0.1*F28*$AC29 -> 1.3210751 | R29: =G28+RAND()*0.1*G28*$AC29 -> 1.7992208 | S29: =H28+RAND()*0.1*H28*$AC29 -> 2.1888386 | T29: =I28+RAND()*0.1*I28*$AC29 -> 4.8221971 | U29: =J28+RAND()*0.1*J28*$AC29 -> 24.019647 | V29: =K28+RAND()*0.1*K28*$AC29 -> 34.124533 | W29: =L28+RAND()*0.1*L28*$AC29 -> 0 | X29: =M28+RAND()*0.1*M28*$AC29 -> 1.6625229 | ... Z29: =O28+RAND()*0.1*O28*$AC29 -> 27.877837 | AB29: =RAND() -> 0.59291595 | AC29: =IF(AB29>0.5,-1,1) -> -1
A31: T6 | B31: =CellCount_Viability!A7 -> 46273 | F31: Maltoheptaose | G31: Maltohexaose | H31: Maltopentao se | I31: Maltotetraose | J31: Maltotriose | K31: Maltose | L31: Glucose | M31: Fructose | N31: Glycerol | O31: Ethanol
A32: MT01-MTT-260_CBS1483_17P-S6a | C32: D2F-A2 | E32: 1 | F32: 1.39 | G32: 1.98 | H32: 2.26 | I32: 5.28 | J32: 23.2485 | K32: 20.3938 | L32: 0 | M32: 0 | N32: 2.266 | O32: 46.4352
A33: MT01-MTT-260_CBS1483_17P-S6b | C33: D2F-B2 | E33: 1 | F33: 1.3415514 | G33: 1.7902537 | H33: 2.0544876 | I33: 4.8921039 | J33: 23.04833 | K33: 18.514024 | L33: 0 | M33: 0 | N33: 2.2077237 | O33: 45.162739 | Q33: =F32+RAND()*0.1*F32*$AC33 -> 1.4752273 | R33: =G32+RAND()*0.1*G32*$AC33 -> 2.0714505 | S33: =H32+RAND()*0.1*H32*$AC33 -> 2.4536448 | T33: =I32+RAND()*0.1*I32*$AC33 -> 5.579612 | U33: =J32+RAND()*0.1*J32*$AC33 -> 25.099984 | V33: =K32+RAND()*0.1*K32*$AC33 -> 21.523233 | W33: =L32+RAND()*0.1*L32*$AC33 -> 0 | X33: =M32+RAND()*0.1*M32*$AC33 -> 0 | ... Z33: =O32+RAND()*0.1*O32*$AC33 -> 49.475637 | AB33: =RAND() -> 0.41798343 | AC33: =IF(AB33>0.5,-1,1) -> 1
A34: MT02-MTT-260_CBS1483_17P-S6a | C34: D2F-C2 | E34: 1 | F34: 1.4428453 | G34: 2.1076895 | H34: 2.4260158 | I34: 5.2795558 | J34: 24.910881 | K34: 21.563167 | L34: 0 | M34: 0 | N34: 2.4365092 | O34: 47.851995 | Q34: =F33+RAND()*0.1*F33*$AC34 -> 1.3833706 | R34: =G33+RAND()*0.1*G33*$AC34 -> 1.9243086 | S34: =H33+RAND()*0.1*H33*$AC34 -> 2.0805157 | T34: =I33+RAND()*0.1*I33*$AC34 -> 5.0501777 | U34: =J33+RAND()*0.1*J33*$AC34 -> 24.305885 | V34: =K33+RAND()*0.1*K33*$AC34 -> 18.889355 | W34: =L33+RAND()*0.1*L33*$AC34 -> 0 | X34: =M33+RAND()*0.1*M33*$AC34 -> 0 | ... Z34: =O33+RAND()*0.1*O33*$AC34 -> 48.422196 | AB34: =RAND() -> 0.26403946 | AC34: =IF(AB34>0.5,-1,1) -> 1
A35: MT02-MTT-260_CBS1483_17P-S6b | C35: D2F-D2 | E35: 1 | F35: 1.3734119 | G35: 1.9096683 | H35: 2.2448415 | I35: 4.7902873 | J35: 21.884508 | K35: 18.960857 | L35: 0 | M35: 0 | N35: 2.2626018 | O35: 43.853855 | Q35: =F34+RAND()*0.1*F34*$AC35 -> 1.4952213 | R35: =G34+RAND()*0.1*G34*$AC35 -> 2.2453494 | S35: =H34+RAND()*0.1*H34*$AC35 -> 2.4657208 | T35: =I34+RAND()*0.1*I34*$AC35 -> 5.7541409 | U35: =J34+RAND()*0.1*J34*$AC35 -> 27.271426 | V35: =K34+RAND()*0.1*K34*$AC35 -> 22.535462 | W35: =L34+RAND()*0.1*L34*$AC35 -> 0 | X35: =M34+RAND()*0.1*M34*$AC35 -> 0 | ... Z35: =O34+RAND()*0.1*O34*$AC35 -> 48.925632 | AB35: =RAND() -> 0.13580745 | AC35: =IF(AB35>0.5,-1,1) -> 1
A37: T7 | B37: =CellCount_Viability!A8 -> 46274 | F37: Maltoheptaose | G37: Maltohexaose | H37: Maltopentao se | I37: Maltotetraose | J37: Maltotriose | K37: Maltose | L37: Glucose | M37: Fructose | N37: Glycerol | O37: Ethanol
A38: MT01-MTT-260_CBS1483_17P-s10a | C38: D2F-A3 | E38: 1 | F38: 1.39 | G38: 1.98 | H38: 2.26 | I38: 5.28 | J38: 20.0915 | K38: 5.1254 | L38: 0 | M38: 0 | N38: 2.5132 | O38: 55.5504
A39: MT01-MTT-260_CBS1483_17P-s10b | C39: D2F-B3 | E39: 1 | F39: 1.4200211 | G39: 2.1163256 | H39: 2.363003 | I39: 5.287183 | J39: 21.62355 | K39: 5.4662063 | L39: 0 | M39: 0 | N39: 2.6982422 | O39: 59.789288 | Q39: =F38+RAND()*0.1*F38*$AC39 -> 1.4825866 | R39: =G38+RAND()*0.1*G38*$AC39 -> 2.0728601 | S39: =H38+RAND()*0.1*H38*$AC39 -> 2.377572 | T39: =I38+RAND()*0.1*I38*$AC39 -> 5.5638047 | U39: =J38+RAND()*0.1*J38*$AC39 -> 20.636439 | V39: =K38+RAND()*0.1*K38*$AC39 -> 5.5085016 | W39: =L38+RAND()*0.1*L38*$AC39 -> 0 | X39: =M38+RAND()*0.1*M38*$AC39 -> 0 | ... Z39: =O38+RAND()*0.1*O38*$AC39 -> 60.027249 | AB39: =RAND() -> 0.18321942 | AC39: =IF(AB39>0.5,-1,1) -> 1
A40: MT02-MTT-260_CBS1483_17P-s10a | C40: D2F-C3 | E40: 1 | F40: 1.4319852 | G40: 2.1142534 | H40: 2.3603221 | I40: 5.7049311 | J40: 20.573138 | K40: 5.4486373 | L40: 0 | M40: 0 | N40: 2.6263488 | O40: 57.510543 | Q40: =F39+RAND()*0.1*F39*$AC40 -> 1.5152236 | R40: =G39+RAND()*0.1*G39*$AC40 -> 2.1359701 | S40: =H39+RAND()*0.1*H39*$AC40 -> 2.367376 | T40: =I39+RAND()*0.1*I39*$AC40 -> 5.3190547 | U40: =J39+RAND()*0.1*J39*$AC40 -> 23.18831 | V40: =K39+RAND()*0.1*K39*$AC40 -> 5.5418862 | W40: =L39+RAND()*0.1*L39*$AC40 -> 0 | X40: =M39+RAND()*0.1*M39*$AC40 -> 0 | ... Z40: =O39+RAND()*0.1*O39*$AC40 -> 63.213861 | AB40: =RAND() -> 0.45660361 | AC40: =IF(AB40>0.5,-1,1) -> 1
A41: MT02-MTT-260_CBS1483_17P-s10b | C41: D2F-D3 | E41: 1 | F41: 1.2755547 | G41: 1.7828081 | H41: 2.1620688 | I41: 5.198952 | J41: 19.276829 | K41: 5.1233166 | L41: 0 | M41: 0 | N41: 2.4416561 | O41: 53.622254 | Q41: =F40+RAND()*0.1*F40*$AC41 -> 1.4420419 | R41: =G40+RAND()*0.1*G40*$AC41 -> 2.3252439 | S41: =H40+RAND()*0.1*H40*$AC41 -> 2.5703294 | T41: =I40+RAND()*0.1*I40*$AC41 -> 5.7335251 | U41: =J40+RAND()*0.1*J40*$AC41 -> 22.545189 | V41: =K40+RAND()*0.1*K40*$AC41 -> 5.9632703 | W41: =L40+RAND()*0.1*L40*$AC41 -> 0 | X41: =M40+RAND()*0.1*M40*$AC41 -> 0 | ... Z41: =O40+RAND()*0.1*O40*$AC41 -> 60.016561 | AB41: =RAND() -> 0.22499596 | AC41: =IF(AB41>0.5,-1,1) -> 1
A43: T8 | B43: =CellCount_Viability!A9 -> 46275 | F43: Maltoheptaose | G43: Maltohexaose | H43: Maltopentao se | I43: Maltotetraose | J43: Maltotriose | K43: Maltose | L43: Glucose | M43: Fructose | N43: Glycerol | O43: Ethanol
A44: MT01-MTT-260_CBS1483_17P-s10a | C44: D2F-A3 | E44: 1 | F44: 1.39 | G44: 1.98 | H44: 2.26 | I44: 5.28 | J44: 18.59 | K44: 3.9053 | L44: 0 | M44: 0 | N44: 2.5132 | O44: 57.6288
A45: MT01-MTT-260_CBS1483_17P-s10b | C45: D2F-B3 | E45: 1 | F45: 1.5268091 | G45: 2.1169051 | H45: 2.4192133 | I45: 5.3362137 | J45: 19.156702 | K45: 4.1677915 | L45: 0 | M45: 0 | N45: 2.5821495 | O45: 62.170092 | Q45: =F44+RAND()*0.1*F44*$AC45 -> 1.3284938 | R45: =G44+RAND()*0.1*G44*$AC45 -> 1.8277656 | S45: =H44+RAND()*0.1*H44*$AC45 -> 2.1125376 | T45: =I44+RAND()*0.1*I44*$AC45 -> 4.9508214 | U45: =J44+RAND()*0.1*J44*$AC45 -> 18.504167 | V45: =K44+RAND()*0.1*K44*$AC45 -> 3.5255294 | W45: =L44+RAND()*0.1*L44*$AC45 -> 0 | X45: =M44+RAND()*0.1*M44*$AC45 -> 0 | ... Z45: =O44+RAND()*0.1*O44*$AC45 -> 52.691174 | AB45: =RAND() -> 0.7717124 | AC45: =IF(AB45>0.5,-1,1) -> -1
A46: MT02-MTT-260_CBS1483_17P-s10a | C46: D2F-C3 | E46: 1 | F46: 1.3517184 | G46: 1.9577415 | H46: 2.0795223 | I46: 5.2249061 | J46: 18.038545 | K46: 3.748334 | L46: 0 | M46: 0 | N46: 2.3351034 | O46: 57.0534 | Q46: =F45+RAND()*0.1*F45*$AC46 -> 1.4689376 | R46: =G45+RAND()*0.1*G45*$AC46 -> 2.1163551 | S46: =H45+RAND()*0.1*H45*$AC46 -> 2.3444131 | T46: =I45+RAND()*0.1*I45*$AC46 -> 5.2949551 | U46: =J45+RAND()*0.1*J45*$AC46 -> 18.425986 | V46: =K45+RAND()*0.1*K45*$AC46 -> 3.7530302 | W46: =L45+RAND()*0.1*L45*$AC46 -> 0 | X46: =M45+RAND()*0.1*M45*$AC46 -> 0 | ... Z46: =O45+RAND()*0.1*O45*$AC46 -> 59.6359 | AB46: =RAND() -> 0.712071 | AC46: =IF(AB46>0.5,-1,1) -> -1
A47: MT02-MTT-260_CBS1483_17P-s10b | C47: D2F-D3 | E47: 1 | F47: 1.4007559 | G47: 2.0773405 | H47: 2.4164429 | I47: 5.7686606 | J47: 19.596897 | K47: 3.9190099 | L47: 0 | M47: 0 | N47: 2.5256059 | O47: 62.967194 | Q47: =F46+RAND()*0.1*F46*$AC47 -> 1.3384552 | R47: =G46+RAND()*0.1*G46*$AC47 -> 1.8992456 | S47: =H46+RAND()*0.1*H46*$AC47 -> 2.0590663 | T47: =I46+RAND()*0.1*I46*$AC47 -> 4.8056618 | U47: =J46+RAND()*0.1*J46*$AC47 -> 17.470342 | V47: =K46+RAND()*0.1*K46*$AC47 -> 3.4606953 | W47: =L46+RAND()*0.1*L46*$AC47 -> 0 | X47: =M46+RAND()*0.1*M46*$AC47 -> 0 | ... Z47: =O46+RAND()*0.1*O46*$AC47 -> 55.913442 | AB47: =RAND() -> 0.93899252 | AC47: =IF(AB47>0.5,-1,1) -> -1
...

Sheet GC_esters_raw
A1: T1 | B1: =CellCount_Viability!A2 -> 46268 | F1: Ethyl acetate | G1: Ethanol | H1: Isobutyl acetate | I1: Ethyl butyrate | J1: Isobutanol | K1: Isoamyl acetate | L1: Isoamyl alcohol | M1: Ethyl hexanoate | N1: Ethyl octanoate | O1: Ethyl decanoate
A2: MT01-MTT-260_CBS1483_17P-S2a | C2: 201 | E2: 1 | F2: 0 | G2: 0 | H2: 0 | I2: 0 | J2: 0.49 | K2: 0 | L2: 3.58 | M2: 0 | N2: 0 | O2: 0
A3: MT01-MTT-260_CBS1483_17P-S2b | C3: 202 | E3: 1 | F3: 0.14 | G3: 0 | H3: 0 | I3: 0 | J3: 0.48 | K3: 0 | L3: 3.46 | M3: 0 | N3: 0 | O3: 0
A4: MT02-MTT-260_CBS1483_17P-S2a | C4: 203 | E4: 1 | F4: 0 | G4: 0 | H4: 0 | I4: 0 | J4: 0.51 | K4: 0 | L4: 3.65 | M4: 0 | N4: 0 | O4: 0
A5: MT02-MTT-260_CBS1483_17P-S2b | C5: 204 | E5: 1 | F5: 0 | G5: 0 | H5: 0 | I5: 0 | J5: 0.47 | K5: 0 | L5: 3.64 | M5: 0 | N5: 0 | O5: 0
A7: T2 | B7: =CellCount_Viability!A3 -> 46269 | F7: Ethyl acetate | G7: Ethanol | H7: Isobutyl acetate | I7: Ethyl butyrate | J7: Isobutanol | K7: Isoamyl acetate | L7: Isoamyl alcohol | M7: Ethyl hexanoate | N7: Ethyl octanoate | O7: Ethyl decanoate
A8: MT01-MTT-260_CBS1483_17P-S2a | C8: 201 | E8: 1 | F8: 0.52 | G8: 0 | H8: 0 | I8: 0.13 | J8: 2.09 | K8: 0.05 | L8: 20.37 | M8: 0 | N8: 0 | O8: 0
A9: MT01-MTT-260_CBS1483_17P-S2b | C9: 202 | E9: 1 | F9: 0.49 | G9: 0 | H9: 0 | I9: 0.14 | J9: 2.24 | K9: 0.09 | L9: 21.61 | M9: 0 | N9: 0 | O9: 0
A10: MT02-MTT-260_CBS1483_17P-S2a | C10: 203 | E10: 1 | F10: 0.47 | G10: 0 | H10: 0 | I10: 0.13 | J10: 1.98 | K10: 0.06 | L10: 19.38 | M10: 0 | N10: 0 | O10: 0
A11: MT02-MTT-260_CBS1483_17P-S2b | C11: 204 | E11: 1 | F11: 0.47 | G11: 0 | H11: 0 | I11: 0.13 | J11: 1.98 | K11: 0.06 | L11: 19.38 | M11: 0 | N11: 0 | O11: 0
A13: T3 | B13: =CellCount_Viability!A4 -> 46270 | F13: Ethyl acetate | G13: Ethanol | H13: Isobutyl acetate | I13: Ethyl butyrate | J13: Isobutanol | K13: Isoamyl acetate | L13: Isoamyl alcohol | M13: Ethyl hexanoate | N13: Ethyl octanoate | O13: Ethyl decanoate
A14: MT01-MTT-260_CBS1483_17P-S2a | C14: 201 | E14: 1 | F14: 6.41 | G14: 0 | H14: 0.0434 | I14: 0.2416 | J14: 4.2972 | K14: 1.2962 | L14: 33.5884 | M14: 0.1736 | N14: 1.1718 | O14: 2.1297
A15: MT01-MTT-260_CBS1483_17P-S2b | C15: 202 | E15: 1 | F15: 6.6125 | G15: 0 | H15: 0.0465 | I15: 0.2578 | J15: 4.5681 | K15: 1.3579 | L15: 35.622 | M15: 0.1767 | N15: 1.116 | O15: 1.9127
A16: MT02-MTT-260_CBS1483_17P-S2a | C16: 203 | E16: 1 | F16: 5.6842 | G16: 0 | H16: 0.0372 | I16: 0.2354 | J16: 4.1345 | K16: 1.1512 | L16: 32.4217 | M16: 0.1643 | N16: 1.1811 | O16: 2.3746
A17: MT02-MTT-260_CBS1483_17P-S2b | C17: 204 | E17: 1 | F17: 5.8454 | G17: 0 | H17: 0.0372 | I17: 0.2416 | J17: 4.2213 | K17: 1.1791 | L17: 33.175 | M17: 0.1705 | N17: 1.1718 | O17: 2.4645
A19: T4 | B19: =CellCount_Viability!A5 -> 46271 | F19: Ethyl acetate | G19: Ethanol | H19: Isobutyl acetate | I19: Ethyl butyrate | J19: Isobutanol | K19: Isoamyl acetate | L19: Isoamyl alcohol | M19: Ethyl hexanoate | N19: Ethyl octanoate | O19: Ethyl decanoate
A20: MT01-MTT-260_CBS1483_17P-S2a | C20: 201 | E20: 1 | F20: 11.92 | G20: 0 | H20: 0.084 | I20: 0.346 | J20: 6.362 | K20: 2.462 | L20: 45.954 | M20: 0.336 | N20: 2.268 | O20: 4.122
A21: MT01-MTT-260_CBS1483_17P-S2b | C21: 202 | E21: 1 | F21: 12.34 | G21: 0 | H21: 0.09 | I21: 0.368 | J21: 6.746 | K21: 2.544 | L21: 48.73 | M21: 0.342 | N21: 2.16 | O21: 3.702
A22: MT02-MTT-260_CBS1483_17P-S2a | C22: 203 | E22: 1 | F22: 10.562 | G22: 0 | H22: 0.072 | I22: 0.334 | J22: 6.15 | K22: 2.172 | L22: 44.622 | M22: 0.318 | N22: 2.286 | O22: 4.596
A23: MT02-MTT-260_CBS1483_17P-S2b | C23: 204 | E23: 1 | F23: 10.874 | G23: 0 | H23: 0.072 | I23: 0.346 | J23: 6.318 | K23: 2.226 | L23: 46.08 | M23: 0.33 | N23: 2.268 | O23: 4.77
A25: T5 | B25: =CellCount_Viability!A6 -> 46272 | F25: Ethyl acetate | G25: Ethanol | H25: Isobutyl acetate | I25: Ethyl butyrate | J25: Isobutanol | K25: Isoamyl acetate | L25: Isoamyl alcohol | M25: Ethyl hexanoate | N25: Ethyl octanoate | O25: Ethyl decanoate
A26: MT01-MTT-260_CBS1483_17P-S5a | C26: D2F-A1 | E26: 1 | F26: 19.52 | G26: 0 | H26: 0.14 | I26: 0.49 | J26: 9.21 | K26: 4.07 | L26: 63.01 | M26: 0.56 | N26: 3.78 | O26: 6.87
A27: MT01-MTT-260_CBS1483_17P-S5b | C27: D2F-B1 | E27: 1 | F27: 20.24 | G27: 0 | H27: 0.15 | I27: 0.52 | J27: 9.75 | K27: 4.18 | L27: 66.81 | M27: 0.57 | N27: 3.6 | O27: 6.17
A28: MT02-MTT-260_CBS1483_17P-S5a | C28: D2F-C1 | E28: 1 | F28: 17.29 | G28: 0 | H28: 0.12 | I28: 0.47 | J28: 8.93 | K28: 3.58 | L28: 61.45 | M28: 0.53 | N28: 3.81 | O28: 7.66
A29: MT02-MTT-260_CBS1483_17P-S5b | C29: D2F-D1 | E29: 1 | F29: 17.81 | G29: 0 | H29: 0.12 | I29: 0.49 | J29: 9.21 | K29: 3.67 | L29: 63.88 | M29: 0.55 | N29: 3.78 | O29: 7.95
A31: T6 | B31: =CellCount_Viability!A7 -> 46273 | F31: Ethyl acetate | G31: Ethanol | H31: Isobutyl acetate | I31: Ethyl butyrate | J31: Isobutanol | K31: Isoamyl acetate | L31: Isoamyl alcohol | M31: Ethyl hexanoate | N31: Ethyl octanoate | O31: Ethyl decanoate
A32: MT01-MTT-260_CBS1483_17P-S6a | C32: D2F-A2 | E32: 1 | F32: 27.49 | G32: 0 | H32: 0.18 | I32: 0.59 | J32: 11.12 | K32: 5.31 | L32: 69.51 | M32: 0.75 | N32: 5.23 | O32: 10.49
A33: MT01-MTT-260_CBS1483_17P-S6b | C33: D2F-B2 | E33: 1 | F33: 27.5 | G33: 0 | H33: 0.18 | I33: 0.59 | J33: 11.22 | K33: 5.32 | L33: 70.06 | M33: 0.75 | N33: 5.31 | O33: 10.84
A34: MT02-MTT-260_CBS1483_17P-S6a | C34: D2F-C2 | E34: 1 | F34: 24.44 | G34: 0 | H34: 0.16 | I34: 0.55 | J34: 10.71 | K34: 4.73 | L34: 66.87 | M34: 0.71 | N34: 5.46 | O34: 12.63
A35: MT02-MTT-260_CBS1483_17P-S6b | C35: D2F-D2 | E35: 1 | F35: 24.38 | G35: 0 | H35: 0.16 | I35: 0.55 | J35: 10.71 | K35: 4.71 | L35: 66.86 | M35: 0.7 | N35: 5.37 | O35: 12.52
A37: T7 | B37: =CellCount_Viability!A8 -> 46274 | F37: Ethyl acetate | G37: Ethanol | H37: Isobutyl acetate | I37: Ethyl butyrate | J37: Isobutanol | K37: Isoamyl acetate | L37: Isoamyl alcohol | M37: Ethyl hexanoate | N37: Ethyl octanoate | O37: Ethyl decanoate
A38: MT01-MTT-260_CBS1483_17P-s10a | C38: D2F-A3 | E38: 1 | F38: 32.286 | G38: 0 | H38: 0.202 | I38: 0.6505 | J38: 12.0495 | K38: 5.9865 | L38: 71.974 | M38: 0.794 | N38: 6.33 | O38: 12.7835
A39: MT01-MTT-260_CBS1483_17P-s10b | C39: D2F-B3 | E39: 1 | F39: 32.3895 | G39: 0 | H39: 0.202 | I39: 0.6505 | J39: 12.1165 | K39: 5.991 | L39: 72.117 | M39: 0.7885 | N39: 6.2945 | O39: 12.93
A40: MT02-MTT-260_CBS1483_17P-s10a | C40: D2F-C3 | E40: 1 | F40: 29.2305 | G40: 0 | H40: 0.182 | I40: 0.616 | J40: 11.81 | K40: 5.412 | L40: 70.247 | M40: 0.7595 | N40: 6.5325 | O40: 14.7585
A41: MT02-MTT-260_CBS1483_17P-s10b | C41: D2F-D3 | E41: 1 | F41: 29.3795 | G41: 0 | H41: 0.182 | I41: 0.6215 | J41: 11.8925 | K41: 5.414 | L41: 70.6935 | M41: 0.7495 | N41: 6.217 | O41: 13.8015
A43: T8 | B43: =CellCount_Viability!A9 -> 46275 | F43: Ethyl acetate | G43: Ethanol | H43: Isobutyl acetate | I43: Ethyl butyrate | J43: Isobutanol | K43: Isoamyl acetate | L43: Isoamyl alcohol | M43: Ethyl hexanoate | N43: Ethyl octanoate | O43: Ethyl decanoate
A44: MT01-MTT-260_CBS1483_17P-s10a | C44: D2F-A3 | E44: 1 | F44: 36.21 | G44: 0 | H44: 0.22 | I44: 0.7 | J44: 12.81 | K44: 6.54 | L44: 73.99 | M44: 0.83 | N44: 7.23 | O44: 14.66
A45: MT01-MTT-260_CBS1483_17P-s10b | C45: D2F-B3 | E45: 1 | F45: 36.39 | G45: 0 | H45: 0.22 | I45: 0.7 | J45: 12.85 | K45: 6.54 | L45: 73.8 | M45: 0.82 | N45: 7.1 | O45: 14.64
A46: MT02-MTT-260_CBS1483_17P-s10a | C46: D2F-C3 | E46: 1 | F46: 33.15 | G46: 0 | H46: 0.2 | I46: 0.67 | J46: 12.71 | K46: 5.97 | L46: 73.01 | M46: 0.8 | N46: 7.41 | O46: 16.5
A47: MT02-MTT-260_CBS1483_17P-s10b | C47: D2F-D3 | E47: 1 | F47: 33.47 | G47: 0 | H47: 0.2 | I47: 0.68 | J47: 12.86 | K47: 5.99 | L47: 73.83 | M47: 0.79 | N47: 6.91 | O47: 14.85
...

Sheet GC_ketones_raw
A1: T1 | B1: =CellCount_Viability!A2 -> 46268 | F1: 2,3-diacetyl | G1: 2,3- pentadione
A2: MT01-MTT-260_CBS1483_17P-s10a | C2: 209 | E2: 1 | F2: 112.435 | G2: 24.69
A3: MT01-MTT-260_CBS1483_17P-s10b | C3: 210 | E3: 1 | F3: 112.435 | G3: 24.69
A4: MT02-MTT-260_CBS1483_17P-s10a | C4: 211 | E4: 1 | F4: 105.03 | G4: 24.5
A5: MT02-MTT-260_CBS1483_17P-s10b | C5: 212 | E5: 1 | F5: 105.03 | G5: 24.5
A7: T2 | B7: =CellCount_Viability!A3 -> 46269 | F7: 2,3-diacetyl | G7: 2,3- pentadione
A8: MT01-MTT-260_CBS1483_17P-S2a | C8: 209 | E8: 1 | F8: 641.48 | G8: 379.37
A9: MT01-MTT-260_CBS1483_17P-S2b | C9: 210 | E9: 1 | F9: 611.17 | G9: 389.17
A10: MT02-MTT-260_CBS1483_17P-S2a | C10: 211 | E10: 1 | F10: 632.63 | G10: 370.91
A11: MT02-MTT-260_CBS1483_17P-S2b | C11: 212 | E11: 1 | F11: 611 | G11: 364.01
A13: T3 | B13: =CellCount_Viability!A4 -> 46270 | F13: 2,3-diacetyl | G13: 2,3- pentadione
A14: MT01-MTT-260_CBS1483_17P-s10a | C14: 209 | E14: 1 | F14: 695 | G14: 412
A15: MT01-MTT-260_CBS1483_17P-s10b | C15: 210 | E15: 1 | F15: 700 | G15: 491
A16: MT02-MTT-260_CBS1483_17P-s10a | C16: 211 | E16: 1 | F16: 685 | G16: 501
A17: MT02-MTT-260_CBS1483_17P-s10b | C17: 212 | E17: 1 | F17: 690 | G17: 473
A19: T4 | B19: =CellCount_Viability!A5 -> 46271 | F19: 2,3-diacetyl | G19: 2,3- pentadione
A20: MT01-MTT-260_CBS1483_17P-S3a | C20: 109 | E20: 1 | F20: 725 | G20: 596.43
A21: MT01-MTT-260_CBS1483_17P-S3b | C21: 110 | E21: 1 | F21: 695 | G21: 647.73
A22: MT02-MTT-260_CBS1483_17P-S3a | C22: 111 | E22: 1 | F22: 529 | G22: 569.36
A23: MT02-MTT-260_CBS1483_17P-S3b | C23: 112 | E23: 1 | F23: 681 | G23: 571.99
A25: T5 | B25: =CellCount_Viability!A6 -> 46272 | F25: 2,3-diacetyl | G25: 2,3- pentadione
A26: MT01-MTT-260_CBS1483_17P-S4a | C26: 309 | E26: 1 | F26: 955.82 | G26: 769.54
A27: MT01-MTT-260_CBS1483_17P-S4b | C27: 310 | E27: 1 | F27: 1097.44 | G27: 832.57
A28: MT02-MTT-260_CBS1483_17P-S4a | C28: 311 | E28: 1 | F28: 642.54 | G28: 740.05
A29: MT02-MTT-260_CBS1483_17P-S4b | C29: 312 | E29: 1 | F29: 999.54 | G29: 738.31
A31: T6 | B31: =CellCount_Viability!A7 -> 46273 | F31: 2,3-diacetyl | G31: 2,3- pentadione
A32: MT01-MTT-260_CBS1483_17P-S5a | C32: 109 | E32: 1 | F32: 583.73 | G32: 765.74
A33: MT01-MTT-260_CBS1483_17P-S5b | C33: 110 | E33: 1 | F33: 620.36 | G33: 784.01
A34: MT02-MTT-260_CBS1483_17P-S5a | C34: 111 | E34: 1 | F34: 584.95 | G34: 857.09
A35: MT02-MTT-260_CBS1483_17P-S5b | C35: 112 | E35: 1 | F35: 594.7 | G35: 860.22
A37: T7 | B37: =CellCount_Viability!A8 -> 46274 | F37: 2,3-diacetyl | G37: 2,3- pentadione
A38: MT01-MTT-260_CBS1483_17P-s10a | C38: D2F-A3 | E38: 1 | F38: 466.43 | G38: 528.45
A39: MT01-MTT-260_CBS1483_17P-s10b | C39: D2F-B3 | E39: 1 | F39: 427.205 | G39: 549.915
A40: MT02-MTT-260_CBS1483_17P-s10a | C40: D2F-C3 | E40: 1 | F40: 403.905 | G40: 593.98
A41: MT02-MTT-260_CBS1483_17P-s10b | C41: D2F-D3 | E41: 1 | F41: 417.265 | G41: 596.8
A43: T8 | B43: =CellCount_Viability!A9 -> 46275 | F43: Maltoheptaose | G43: Maltohexaose
A44: MT01-MTT-260_CBS1483_17P-s10a | C44: D2F-A3 | E44: 1 | F44: 419.51 | G44: 433.534
A45: MT01-MTT-260_CBS1483_17P-s10b | C45: D2F-B3 | E45: 1 | F45: 349.943 | G45: 456.277
A46: MT02-MTT-260_CBS1483_17P-s10a | C46: D2F-C3 | E46: 1 | F46: 331.487 | G46: 488.736
A47: MT02-MTT-260_CBS1483_17P-s10b | C47: D2F-D3 | E47: 1 | F47: 346.291 | G47: 491.432
...

Sheet HPLC
A1: Date | B1: Time (h) | C1: Time (days) | D1: 1 Maltotriose | E1: 1 Maltose | F1: 1 Glucose | G1: 1 Fructose | H1: 1 Glycerol | I1: 1 Ethanol | J1: 2 Maltotriose | K1: 2 Maltose | L1: 2 Glucose | M1: 2 Fructose | N1: 2 Glycerol | O1: 2 Ethanol | P1: StDev 1 Maltotriose | Q1: StDev 1 Maltose | R1: StDev 1 Glucose | S1: StDev 1 Fructose | T1: StDev 1 Glycerol | U1: StDev 1 Ethanol | V1: StDev 2 Maltotriose | W1: StDev 2 Maltose | X1: StDev 2 Glucose | Y1: StDev 2 Fructose | Z1: StDev 2 Glycerol | AA1: StDev 2 Ethanol
A2: =CellCount_Viability!A2 -> 46268 | B2: =C2*24 -> 0 | C2: =IF(NOT(A2=0),A2-$A$2,"") -> 0 | D2: =AVERAGE(HPLC_raw!J2:J3) -> 28.1675 | E2: =AVERAGE(HPLC_raw!K2:K3) -> 87.021917 | F2: =AVERAGE(HPLC_raw!L2:L3) -> 20.535598 | G2: =AVERAGE(HPLC_raw!M2:M3) -> 7.9514809 | H2: =AVERAGE(HPLC_raw!N2:N3) -> 0 | I2: =AVERAGE(HPLC_raw!O2:O3) -> 0.7969338 | J2: =AVERAGE(HPLC_raw!J4:J5) -> 25.243706 | K2: =AVERAGE(HPLC_raw!K4:K5) -> 82.320355 | L2: =AVERAGE(HPLC_raw!L4:L5) -> 19.089426 | M2: =AVERAGE(HPLC_raw!M4:M5) -> 7.3261667 | N2: =AVERAGE(HPLC_raw!N4:N5) -> 0 | O2: =AVERAGE(HPLC_raw!O4:O5) -> 0.70886325 | P2: =STDEV(HPLC_raw!J2:J3) -> 1.7325746 | Q2: =STDEV(HPLC_raw!K2:K3) -> 0.97230248 | R2: =STDEV(HPLC_raw!L2:L3) -> 0.41484279 | S2: =STDEV(HPLC_raw!M2:M3) -> 0.13471216 | T2: =STDEV(HPLC_raw!N2:N3) -> 0 | U2: =STDEV(HPLC_raw!O2:O3) -> 0.034575822 | V2: =STDEV(HPLC_raw!J4:J5) -> 0.039606267 | W2: =STDEV(HPLC_raw!K4:K5) -> 5.3254912 | X2: =STDEV(HPLC_raw!L4:L5) -> 1.1590941 | Y2: =STDEV(HPLC_raw!M4:M5) -> 0.30190813 | Z2: =STDEV(HPLC_raw!N4:N5) -> 0 | AA2: =STDEV(HPLC_raw!O4:O5) -> 0.014636602
A3: =CellCount_Viability!A3 -> 46269 | B3: =C3*24 -> 24 | C3: =IF(NOT(A3=0),A3-$A$2,"") -> 1 | D3: =AVERAGE(HPLC_raw!J8:J9) -> 29.152837 | E3: =AVERAGE(HPLC_raw!K8:K9) -> 80.878274 | F3: =AVERAGE(HPLC_raw!L8:L9) -> 15.086307 | G3: =AVERAGE(HPLC_raw!M8:M9) -> 6.3733441 | H3: =AVERAGE(HPLC_raw!N8:N9) -> 0.46557265 | I3: =AVERAGE(HPLC_raw!O8:O9) -> 3.9605061 | J3: =AVERAGE(HPLC_raw!J10:J11) -> 29.43884 | K3: =AVERAGE(HPLC_raw!K10:K11) -> 84.477504 | L3: =AVERAGE(HPLC_raw!L10:L11) -> 16.409119 | M3: =AVERAGE(HPLC_raw!M10:M11) -> 6.7111021 | N3: =AVERAGE(HPLC_raw!N10:N11) -> 0.46778609 | O3: =AVERAGE(HPLC_raw!O10:O11) -> 4.3177506 | P3: =STDEV(HPLC_raw!J8:J9) -> 1.3496363 | Q3: =STDEV(HPLC_raw!K8:K9) -> 1.9664267 | R3: =STDEV(HPLC_raw!L8:L9) -> 0.041445857 | S3: =STDEV(HPLC_raw!M8:M9) -> 0.011800341 | T3: =STDEV(HPLC_raw!N8:N9) -> 0.024780767 | U3: =STDEV(HPLC_raw!O8:O9) -> 0.021080416 | V3: =STDEV(HPLC_raw!J10:J11) -> 0.036873877 | W3: =STDEV(HPLC_raw!K10:K11) -> 0.73890254 | X3: =STDEV(HPLC_raw!L10:L11) -> 0.036149897 | Y3: =STDEV(HPLC_raw!M10:M11) -> 0.016726562 | Z3: =STDEV(HPLC_raw!N10:N11) -> 0.018569507 | AA3: =STDEV(HPLC_raw!O10:O11) -> 0.018289806
A4: =CellCount_Viability!A4 -> 46270 | B4: =C4*24 -> 48 | C4: =IF(NOT(A4=0),A4-$A$2,"") -> 2 | D4: =AVERAGE(HPLC_raw!J14:J15) -> 25.93924 | E4: =AVERAGE(HPLC_raw!K14:K15) -> 72.553065 | F4: =AVERAGE(HPLC_raw!L14:L15) -> 13.734819 | G4: =AVERAGE(HPLC_raw!M14:M15) -> 6.0395718 | H4: =AVERAGE(HPLC_raw!N14:N15) -> 0.42136597 | I4: =AVERAGE(HPLC_raw!O14:O15) -> 3.6678963 | J4: =AVERAGE(HPLC_raw!J16:J17) -> 25.037948 | K4: =AVERAGE(HPLC_raw!K16:K17) -> 72.260466 | L4: =AVERAGE(HPLC_raw!L16:L17) -> 13.647155 | M4: =AVERAGE(HPLC_raw!M16:M17) -> 5.7389394 | N4: =AVERAGE(HPLC_raw!N16:N17) -> 0.38886738 | O4: =AVERAGE(HPLC_raw!O16:O17) -> 3.4566055 | P4: =STDEV(HPLC_raw!J14:J15) -> 1.2011409 | Q4: =STDEV(HPLC_raw!K14:K15) -> 4.1865594 | R4: =STDEV(HPLC_raw!L14:L15) -> 0.80515506 | S4: =STDEV(HPLC_raw!M14:M15) -> 0.010151485 | T4: =STDEV(HPLC_raw!N14:N15) -> 0.0060549912 | U4: =STDEV(HPLC_raw!O14:O15) -> 0.11373635 | V4: =STDEV(HPLC_raw!J16:J17) -> 0.18554943 | W4: =STDEV(HPLC_raw!K16:K17) -> 4.0437329 | X4: =STDEV(HPLC_raw!L16:L17) -> 0.78684675 | Y4: =STDEV(HPLC_raw!M16:M17) -> 0.10818026 | Z4: =STDEV(HPLC_raw!N16:N17) -> 0.0048447281 | AA4: =STDEV(HPLC_raw!O16:O17) -> 0.046255952
A5: =CellCount_Viability!A5 -> 46271 | B5: =C5*24 -> 72 | C5: =IF(NOT(A5=0),A5-$A$2,"") -> 3 | D5: =AVERAGE(HPLC_raw!J20:J21) -> 26.198906 | E5: =AVERAGE(HPLC_raw!K20:K21) -> 54.021006 | F5: =AVERAGE(HPLC_raw!L20:L21) -> 3.2191001 | G5: =AVERAGE(HPLC_raw!M20:M21) -> 3.6071905 | H5: =AVERAGE(HPLC_raw!N20:N21) -> 1.4983336 | I5: =AVERAGE(HPLC_raw!O20:O21) -> 25.369205 | J5: =AVERAGE(HPLC_raw!J22:J23) -> 25.770672 | K5: =AVERAGE(HPLC_raw!K22:K23) -> 56.898494 | L5: =AVERAGE(HPLC_raw!L22:L23) -> 3.3248026 | M5: =AVERAGE(HPLC_raw!M22:M23) -> 3.7254671 | N5: =AVERAGE(HPLC_raw!N22:N23) -> 1.5141592 | O5: =AVERAGE(HPLC_raw!O22:O23) -> 26.053413 | P5: =STDEV(HPLC_raw!J20:J21) -> 0.24549943 | Q5: =STDEV(HPLC_raw!K20:K21) -> 1.6444391 | R5: =STDEV(HPLC_raw!L20:L21) -> 0.013647077 | S5: =STDEV(HPLC_raw!M20:M21) -> 0.091300986 | T5: =STDEV(HPLC_raw!N20:N21) -> 0.02229704 | U5: =STDEV(HPLC_raw!O20:O21) -> 1.4713402 | V5: =STDEV(HPLC_raw!J22:J23) -> 2.3613021 | W5: =STDEV(HPLC_raw!K22:K23) -> 3.2464244 | X5: =STDEV(HPLC_raw!L22:L23) -> 0.31056123 | Y5: =STDEV(HPLC_raw!M22:M23) -> 0.26674656 | Z5: =STDEV(HPLC_raw!N22:N23) -> 0.05903025 | AA5: =STDEV(HPLC_raw!O22:O23) -> 1.9362879
A6: =CellCount_Viability!A6 -> 46272 | B6: =C6*24 -> 96 | C6: =IF(NOT(A6=0),A6-$A$2,"") -> 4 | D6: =AVERAGE(HPLC_raw!J26:J27) -> 25.586739 | E6: =AVERAGE(HPLC_raw!K26:K27) -> 37.332759 | F6: =AVERAGE(HPLC_raw!L26:L27) -> 0 | G6: =AVERAGE(HPLC_raw!M26:M27) -> 1.82998 | H6: =AVERAGE(HPLC_raw!N26:N27) -> 2.056515 | I6: =AVERAGE(HPLC_raw!O26:O27) -> 34.975116 | J6: =AVERAGE(HPLC_raw!J28:J29) -> 24.635626 | K6: =AVERAGE(HPLC_raw!K28:K29) -> 33.55376 | L6: =AVERAGE(HPLC_raw!L28:L29) -> 0 | M6: =AVERAGE(HPLC_raw!M28:M29) -> 1.6701971 | N6: =AVERAGE(HPLC_raw!N28:N29) -> 1.7962519 | O6: =AVERAGE(HPLC_raw!O28:O29) -> 32.341585 | P6: =STDEV(HPLC_raw!J26:J27) -> 0.75552862 | Q6: =STDEV(HPLC_raw!K26:K27) -> 1.302292 | R6: =STDEV(HPLC_raw!L26:L27) -> 0 | S6: =STDEV(HPLC_raw!M26:M27) -> 0.089067103 | T6: =STDEV(HPLC_raw!N26:N27) -> 0.11160267 | U6: =STDEV(HPLC_raw!O26:O27) -> 1.3812847 | V6: =STDEV(HPLC_raw!J28:J29) -> 0.26492942 | W6: =STDEV(HPLC_raw!K28:K29) -> 1.0510587 | X6: =STDEV(HPLC_raw!L28:L29) -> 0 | Y6: =STDEV(HPLC_raw!M28:M29) -> 0.067911398 | Z6: =STDEV(HPLC_raw!N28:N29) -> 0.015911105 | AA6: =STDEV(HPLC_raw!O28:O29) -> 2.1705482
A7: =CellCount_Viability!A7 -> 46273 | B7: =C7*24 -> 120 | C7: =IF(NOT(A7=0),A7-$A$2,"") -> 5 | D7: =AVERAGE(HPLC_raw!J32:J33) -> 23.148415 | E7: =AVERAGE(HPLC_raw!K32:K33) -> 19.453912 | F7: =AVERAGE(HPLC_raw!L32:L33) -> 0 | G7: =AVERAGE(HPLC_raw!M32:M33) -> 0 | H7: =AVERAGE(HPLC_raw!N32:N33) -> 2.2368618 | I7: =AVERAGE(HPLC_raw!O32:O33) -> 45.798969 | J7: =AVERAGE(HPLC_raw!J34:J35) -> 23.397695 | K7: =AVERAGE(HPLC_raw!K34:K35) -> 20.262012 | L7: =AVERAGE(HPLC_raw!L34:L35) -> 0 | M7: =AVERAGE(HPLC_raw!M34:M35) -> 0 | N7: =AVERAGE(HPLC_raw!N34:N35) -> 2.3495555 | O7: =AVERAGE(HPLC_raw!O34:O35) -> 45.852925 | P7: =STDEV(HPLC_raw!J32:J33) -> 0.14154166 | Q7: =STDEV(HPLC_raw!K32:K33) -> 1.3292025 | R7: =STDEV(HPLC_raw!L32:L33) -> 0 | S7: =STDEV(HPLC_raw!M32:M33) -> 0 | T7: =STDEV(HPLC_raw!N32:N33) -> 0.041207577 | U7: =STDEV(HPLC_raw!O32:O33) -> 0.8997658 | V7: =STDEV(HPLC_raw!J34:J35) -> 2.1399689 | W7: =STDEV(HPLC_raw!K34:K35) -> 1.840111 | X7: =STDEV(HPLC_raw!L34:L35) -> 0 | Y7: =STDEV(HPLC_raw!M34:M35) -> 0 | Z7: =STDEV(HPLC_raw!N34:N35) -> 0.12297109 | AA7: =STDEV(HPLC_raw!O34:O35) -> 2.827112
A8: =CellCount_Viability!A8 -> 46274 | B8: =C8*24 -> 144 | C8: =IF(NOT(A8=0),A8-$A$2,"") -> 6 | D8: =AVERAGE(HPLC_raw!J38:J39) -> 20.857525 | E8: =AVERAGE(HPLC_raw!K38:K39) -> 5.2958032 | F8: =AVERAGE(HPLC_raw!L38:L39) -> 0 | G8: =AVERAGE(HPLC_raw!M38:M39) -> 0 | H8: =AVERAGE(HPLC_raw!N38:N39) -> 2.6057211 | I8: =AVERAGE(HPLC_raw!O38:O39) -> 57.669844 | J8: =AVERAGE(HPLC_raw!J40:J41) -> 19.924984 | K8: =AVERAGE(HPLC_raw!K40:K41) -> 5.2859769 | L8: =AVERAGE(HPLC_raw!L40:L41) -> 0 | M8: =AVERAGE(HPLC_raw!M40:M41) -> 0 | N8: =AVERAGE(HPLC_raw!N40:N41) -> 2.5340025 | O8: =AVERAGE(HPLC_raw!O40:O41) -> 55.566399 | P8: =STDEV(HPLC_raw!J38:J39) -> 1.083323 | Q8: =STDEV(HPLC_raw!K38:K39) -> 0.24098645 | R8: =STDEV(HPLC_raw!L38:L39) -> 0 | S8: =STDEV(HPLC_raw!M38:M39) -> 0 | T8: =STDEV(HPLC_raw!N38:N39) -> 0.13084461 | U8: =STDEV(HPLC_raw!O38:O39) -> 2.9973463 | V8: =STDEV(HPLC_raw!J40:J41) -> 0.91662898 | W8: =STDEV(HPLC_raw!K40:K41) -> 0.23003645 | X8: =STDEV(HPLC_raw!L40:L41) -> 0 | Y8: =STDEV(HPLC_raw!M40:M41) -> 0 | Z8: =STDEV(HPLC_raw!N40:N41) -> 0.1305974 | AA8: =STDEV(HPLC_raw!O40:O41) -> 2.7494358
A9: =CellCount_Viability!A9 -> 46275 | B9: =C9*24 -> 168 | C9: =IF(NOT(A9=0),A9-$A$2,"") -> 7 | D9: =AVERAGE(HPLC_raw!J44:J45) -> 18.873351 | E9: =AVERAGE(HPLC_raw!K44:K45) -> 4.0365458 | F9: =AVERAGE(HPLC_raw!L44:L45) -> 0 | G9: =AVERAGE(HPLC_raw!M44:M45) -> 0 | H9: =AVERAGE(HPLC_raw!N44:N45) -> 2.5476748 | I9: =AVERAGE(HPLC_raw!O44:O45) -> 59.899446 | J9: =AVERAGE(HPLC_raw!J46:J47) -> 18.817721 | K9: =AVERAGE(HPLC_raw!K46:K47) -> 3.8336719 | L9: =AVERAGE(HPLC_raw!L46:L47) -> 0 | M9: =AVERAGE(HPLC_raw!M46:M47) -> 0 | N9: =AVERAGE(HPLC_raw!N46:N47) -> 2.4303547 | O9: =AVERAGE(HPLC_raw!O46:O47) -> 60.010297 | P9: =STDEV(HPLC_raw!J44:J45) -> 0.40071887 | Q9: =STDEV(HPLC_raw!K44:K45) -> 0.18560955 | R9: =STDEV(HPLC_raw!L44:L45) -> 0 | S9: =STDEV(HPLC_raw!M44:M45) -> 0 | T9: =STDEV(HPLC_raw!N44:N45) -> 0.048754689 | U9: =STDEV(HPLC_raw!O44:O45) -> 3.2111784 | V9: =STDEV(HPLC_raw!J46:J47) -> 1.1019217 | W9: =STDEV(HPLC_raw!K46:K47) -> 0.12068612 | X9: =STDEV(HPLC_raw!L46:L47) -> 0 | Y9: =STDEV(HPLC_raw!M46:M47) -> 0 | Z9: =STDEV(HPLC_raw!N46:N47) -> 0.13470559 | AA9: =STDEV(HPLC_raw!O46:O47) -> 4.1816835
A10: =CellCount_Viability!A10 -> 46276 | B10: =C10*24 -> 192 | C10: =IF(NOT(A10=0),A10-$A$2,"") -> 8 | D10: =AVERAGE(HPLC_raw!J50:J51) -> 17.28397 | E10: =AVERAGE(HPLC_raw!K50:K51) -> 3.4092523 | F10: =AVERAGE(HPLC_raw!L50:L51) -> 0 | G10: =AVERAGE(HPLC_raw!M50:M51) -> 0 | H10: =AVERAGE(HPLC_raw!N50:N51) -> 2.5514006 | I10: =AVERAGE(HPLC_raw!O50:O51) -> 56.742135 | J10: =AVERAGE(HPLC_raw!J52:J53) -> 17.87593 | K10: =AVERAGE(HPLC_raw!K52:K53) -> 3.4874922 | L10: =AVERAGE(HPLC_raw!L52:L53) -> 0 | M10: =AVERAGE(HPLC_raw!M52:M53) -> 0 | N10: =AVERAGE(HPLC_raw!N52:N53) -> 2.5503368 | O10: =AVERAGE(HPLC_raw!O52:O53) -> 59.353235 | P10: =STDEV(HPLC_raw!J50:J51) -> 0.92918033 | Q10: =STDEV(HPLC_raw!K50:K51) -> 0.04320104 | R10: =STDEV(HPLC_raw!L50:L51) -> 0 | S10: =STDEV(HPLC_raw!M50:M51) -> 0 | T10: =STDEV(HPLC_raw!N50:N51) -> 0.033374529 | U10: =STDEV(HPLC_raw!O50:O51) -> 1.6069213 | V10: =STDEV(HPLC_raw!J52:J53) -> 0.60277999 | W10: =STDEV(HPLC_raw!K52:K53) -> 0.14507712 | X10: =STDEV(HPLC_raw!L52:L53) -> 0 | Y10: =STDEV(HPLC_raw!M52:M53) -> 0 | Z10: =STDEV(HPLC_raw!N52:N53) -> 0.05503169 | AA10: =STDEV(HPLC_raw!O52:O53) -> 3.8794296
A11: =CellCount_Viability!A11 -> 46277 | B11: =C11*24 -> 216 | C11: =IF(NOT(A11=0),A11-$A$2,"") -> 9 | D11: =AVERAGE(HPLC_raw!J56:J57) -> 17.490102 | E11: =AVERAGE(HPLC_raw!K56:K57) -> 3.2838209 | F11: =AVERAGE(HPLC_raw!L56:L57) -> 0 | G11: =AVERAGE(HPLC_raw!M56:M57) -> 0 | H11: =AVERAGE(HPLC_raw!N56:N57) -> 2.5287168 | I11: =AVERAGE(HPLC_raw!O56:O57) -> 55.565547 | J11: =AVERAGE(HPLC_raw!J58:J59) -> 18.086638 | K11: =AVERAGE(HPLC_raw!K58:K59) -> 3.224084 | L11: =AVERAGE(HPLC_raw!L58:L59) -> 0 | M11: =AVERAGE(HPLC_raw!M58:M59) -> 0 | N11: =AVERAGE(HPLC_raw!N58:N59) -> 2.6404043 | O11: =AVERAGE(HPLC_raw!O58:O59) -> 57.801069 | P11: =STDEV(HPLC_raw!J56:J57) -> 0.32653898 | Q11: =STDEV(HPLC_raw!K56:K57) -> 0.026557699 | R11: =STDEV(HPLC_raw!L56:L57) -> 0 | S11: =STDEV(HPLC_raw!M56:M57) -> 0 | T11: =STDEV(HPLC_raw!N56:N57) -> 0.050887904 | U11: =STDEV(HPLC_raw!O56:O57) -> 3.1011623 | V11: =STDEV(HPLC_raw!J58:J59) -> 1.0108384 | W11: =STDEV(HPLC_raw!K58:K59) -> 0.15430631 | X11: =STDEV(HPLC_raw!L58:L59) -> 0 | Y11: =STDEV(HPLC_raw!M58:M59) -> 0 | Z11: =STDEV(HPLC_raw!N58:N59) -> 0.1644438 | AA11: =STDEV(HPLC_raw!O58:O59) -> 7.6978347
A12: =CellCount_Viability!A12 -> 46278 | B12: =C12*24 -> 240 | C12: =IF(NOT(A12=0),A12-$A$2,"") -> 10 | D12: =AVERAGE(HPLC_raw!J62:J63) -> 18.14665 | E12: =AVERAGE(HPLC_raw!K62:K63) -> 3.2796544 | F12: =AVERAGE(HPLC_raw!L62:L63) -> 0 | G12: =AVERAGE(HPLC_raw!M62:M63) -> 0 | H12: =AVERAGE(HPLC_raw!N62:N63) -> 2.5833971 | I12: =AVERAGE(HPLC_raw!O62:O63) -> 61.048504 | J12: =AVERAGE(HPLC_raw!J59:J60) -> 18.801409 | K12: =AVERAGE(HPLC_raw!K59:K60) -> 3.3331951 | L12: =AVERAGE(HPLC_raw!L59:L60) -> 0 | M12: =AVERAGE(HPLC_raw!M59:M60) -> 0 | N12: =AVERAGE(HPLC_raw!N59:N60) -> 2.7566837 | O12: =AVERAGE(HPLC_raw!O59:O60) -> 63.24426 | P12: =STDEV(HPLC_raw!J62:J63) -> 0.94419916 | Q12: =STDEV(HPLC_raw!K62:K63) -> 0.11307261 | R12: =STDEV(HPLC_raw!L62:L63) -> 0 | S12: =STDEV(HPLC_raw!M62:M63) -> 0 | T12: =STDEV(HPLC_raw!N62:N63) -> 0.070140871 | U12: =STDEV(HPLC_raw!O62:O63) -> 3.8111698 | V12: =STDEV(HPLC_raw!J59:J60) -> #DIV/0! | W12: =STDEV(HPLC_raw!K59:K60) -> #DIV/0! | X12: =STDEV(HPLC_raw!L59:L60) -> #DIV/0! | Y12: =STDEV(HPLC_raw!M59:M60) -> #DIV/0! | Z12: =STDEV(HPLC_raw!N59:N60) -> #DIV/0! | AA12: =STDEV(HPLC_raw!O59:O60) -> #DIV/0!
A13: =CellCount_Viability!A13 -> 0 | B13: =C13*24 -> #VALUE! | C13: =IF(NOT(A13=0),A13-$A$2,"") | D13: =AVERAGE(HPLC_raw!J68:J69) -> #N/A | E13: =AVERAGE(HPLC_raw!K68:K69) -> #N/A | F13: =AVERAGE(HPLC_raw!L68:L69) -> #N/A | G13: =AVERAGE(HPLC_raw!M68:M69) -> #N/A | H13: =AVERAGE(HPLC_raw!N68:N69) -> #N/A | I13: =AVERAGE(HPLC_raw!O68:O69) -> #N/A | J13: =AVERAGE(HPLC_raw!J70:J71) -> #N/A | K13: =AVERAGE(HPLC_raw!K70:K71) -> #N/A | L13: =AVERAGE(HPLC_raw!L70:L71) -> #N/A | M13: =AVERAGE(HPLC_raw!M70:M71) -> #N/A | N13: =AVERAGE(HPLC_raw!N70:N71) -> #N/A | O13: =AVERAGE(HPLC_raw!O70:O71) -> #N/A | P13: =STDEV(HPLC_raw!J68:J69) -> #N/A | Q13: =STDEV(HPLC_raw!K68:K69) -> #N/A | R13: =STDEV(HPLC_raw!L68:L69) -> #N/A | S13: =STDEV(HPLC_raw!M68:M69) -> #N/A | T13: =STDEV(HPLC_raw!N68:N69) -> #N/A | U13: =STDEV(HPLC_raw!O68:O69) -> #N/A | V13: =STDEV(HPLC_raw!J70:J71) -> #N/A | W13: =STDEV(HPLC_raw!K70:K71) -> #N/A | X13: =STDEV(HPLC_raw!L70:L71) -> #N/A | Y13: =STDEV(HPLC_raw!M70:M71) -> #N/A | Z13: =STDEV(HPLC_raw!N70:N71) -> #N/A | AA13: =STDEV(HPLC_raw!O70:O71) -> #N/A
A14: =CellCount_Viability!A14 -> 0 | B14: =C14*24 -> #VALUE! | C14: =IF(NOT(A14=0),A14-$A$2,"") | D14: =AVERAGE(HPLC_raw!J74:J75) -> #N/A | E14: =AVERAGE(HPLC_raw!K74:K75) -> #N/A | F14: =AVERAGE(HPLC_raw!L74:L75) -> #N/A | G14: =AVERAGE(HPLC_raw!M74:M75) -> #N/A | H14: =AVERAGE(HPLC_raw!N74:N75) -> #N/A | I14: =AVERAGE(HPLC_raw!O74:O75) -> #N/A | J14: =AVERAGE(HPLC_raw!J76:J77) -> #N/A | K14: =AVERAGE(HPLC_raw!K76:K77) -> #N/A | L14: =AVERAGE(HPLC_raw!L76:L77) -> #N/A | M14: =AVERAGE(HPLC_raw!M76:M77) -> #N/A | N14: =AVERAGE(HPLC_raw!N76:N77) -> #N/A | O14: =AVERAGE(HPLC_raw!O76:O77) -> #N/A | P14: =STDEV(HPLC_raw!J74:J75) -> #N/A | Q14: =STDEV(HPLC_raw!K74:K75) -> #N/A | R14: =STDEV(HPLC_raw!L74:L75) -> #N/A | S14: =STDEV(HPLC_raw!M74:M75) -> #N/A | T14: =STDEV(HPLC_raw!N74:N75) -> #N/A | U14: =STDEV(HPLC_raw!O74:O75) -> #N/A | V14: =STDEV(HPLC_raw!J76:J77) -> #N/A | W14: =STDEV(HPLC_raw!K76:K77) -> #N/A | X14: =STDEV(HPLC_raw!L76:L77) -> #N/A | Y14: =STDEV(HPLC_raw!M76:M77) -> #N/A | Z14: =STDEV(HPLC_raw!N76:N77) -> #N/A | AA14: =STDEV(HPLC_raw!O76:O77) -> #N/A
A15: =CellCount_Viability!A15 -> 0 | B15: =C15*24 -> #VALUE! | C15: =IF(NOT(A15=0),A15-$A$2,"") | D15: =AVERAGE(HPLC_raw!J80:J81) -> #N/A | E15: =AVERAGE(HPLC_raw!K80:K81) -> #N/A | F15: =AVERAGE(HPLC_raw!L80:L81) -> #N/A | G15: =AVERAGE(HPLC_raw!M80:M81) -> #N/A | H15: =AVERAGE(HPLC_raw!N80:N81) -> #N/A | I15: =AVERAGE(HPLC_raw!O80:O81) -> #N/A | J15: =AVERAGE(HPLC_raw!J82:J83) -> #N/A | K15: =AVERAGE(HPLC_raw!K82:K83) -> #N/A | L15: =AVERAGE(HPLC_raw!L82:L83) -> #N/A | M15: =AVERAGE(HPLC_raw!M82:M83) -> #N/A | N15: =AVERAGE(HPLC_raw!N82:N83) -> #N/A | O15: =AVERAGE(HPLC_raw!O82:O83) -> #N/A | P15: =STDEV(HPLC_raw!J80:J81) -> #N/A | Q15: =STDEV(HPLC_raw!K80:K81) -> #N/A | R15: =STDEV(HPLC_raw!L80:L81) -> #N/A | S15: =STDEV(HPLC_raw!M80:M81) -> #N/A | T15: =STDEV(HPLC_raw!N80:N81) -> #N/A | U15: =STDEV(HPLC_raw!O80:O81) -> #N/A | V15: =STDEV(HPLC_raw!J82:J83) -> #N/A | W15: =STDEV(HPLC_raw!K82:K83) -> #N/A | X15: =STDEV(HPLC_raw!L82:L83) -> #N/A | Y15: =STDEV(HPLC_raw!M82:M83) -> #N/A | Z15: =STDEV(HPLC_raw!N82:N83) -> #N/A | AA15: =STDEV(HPLC_raw!O82:O83) -> #N/A
